<?xml version='1.0' ?>
<sdf version='1.12'>
  <world name='default'>
    <gravity>0 0 -9.8</gravity>
    <magnetic_field>5.5645e-6 22.8758e-6 -42.3884e-6</magnetic_field>

    <physics name='default_physics' type='ode'>
      <max_step_size>0.001</max_step_size>
      <real_time_factor>1</real_time_factor>
    </physics>

    <scene>
      <ambient>0.4 0.4 0.4 1</ambient>
      <background>0.7 0.7 0.7 1</background>
      <shadows>true</shadows>
    </scene>

    <!-- Ground plane -->
    <model name='ground_plane'>
      <static>true</static>
      <link name='link'>
        <collision name='collision'>
          <geometry>
            <plane>
              <normal>0 0 1</normal>
              <size>100 100</size>
            </plane>
          </geometry>
        </collision>
        <visual name='visual'>
          <geometry>
            <plane>
              <normal>0 0 1</normal>
              <size>100 100</size>
            </plane>
          </geometry>
          <material>
            <ambient>0.8 0.8 0.8 1</ambient>
            <diffuse>0.8 0.8 0.8 1</diffuse>
          </material>
        </visual>
      </link>
    </model>

    <!-- A simple box robot -->
    <model name='box_robot'>
      <pose>0 0 0.5 0 0 0</pose>
      <link name='chassis'>
        <inertial>
          <mass>10</mass>
          <inertia>
            <ixx>0.833</ixx>
            <iyy>0.833</iyy>
            <izz>0.833</izz>
            <ixy>0</ixy>
            <ixz>0</ixz>
            <iyz>0</iyz>
          </inertia>
        </inertial>
        <collision name='collision'>
          <geometry>
            <box>
              <size>1 0.5 0.25</size>
            </box>
          </geometry>
        </collision>
        <visual name='visual'>
          <geometry>
            <box>
              <size>1 0.5 0.25</size>
            </box>
          </geometry>
          <material>
            <ambient>0.2 0.2 0.8 1</ambient>
            <diffuse>0.2 0.2 0.8 1</diffuse>
          </material>
        </visual>
        <sensor name='camera' type='camera'>
          <pose>0.5 0 0.15 0 0 0</pose>
          <update_rate>30</update_rate>
          <camera>
            <horizontal_fov>1.047</horizontal_fov>
            <image>
              <width>640</width>
              <height>480</height>
              <format>R8G8B8</format>
            </image>
            <clip>
              <near>0.1</near>
              <far>100</far>
            </clip>
          </camera>
        </sensor>
        <sensor name='imu_sensor' type='imu'>
          <update_rate>100</update_rate>
        </sensor>
      </link>

      <link name='left_wheel'>
        <pose>-0.3 0.3 -0.1 -1.5707 0 0</pose>
        <inertial>
          <mass>1</mass>
        </inertial>
        <collision name='collision'>
          <geometry>
            <cylinder>
              <radius>0.15</radius>
              <length>0.05</length>
            </cylinder>
          </geometry>
        </collision>
        <visual name='visual'>
          <geometry>
            <cylinder>
              <radius>0.15</radius>
              <length>0.05</length>
            </cylinder>
          </geometry>
        </visual>
      </link>

      <link name='right_wheel'>
        <pose>-0.3 -0.3 -0.1 -1.5707 0 0</pose>
        <inertial>
          <mass>1</mass>
        </inertial>
        <collision name='collision'>
          <geometry>
            <cylinder>
              <radius>0.15</radius>
              <length>0.05</length>
            </cylinder>
          </geometry>
        </collision>
        <visual name='visual'>
          <geometry>
            <cylinder>
              <radius>0.15</radius>
              <length>0.05</length>
            </cylinder>
          </geometry>
        </visual>
      </link>

      <link name='caster'>
        <pose>0.35 0 -0.125 0 0 0</pose>
        <inertial>
          <mass>0.5</mass>
        </inertial>
        <collision name='collision'>
          <geometry>
            <sphere>
              <radius>0.05</radius>
            </sphere>
          </geometry>
        </collision>
        <visual name='visual'>
          <geometry>
            <sphere>
              <radius>0.05</radius>
            </sphere>
          </geometry>
        </visual>
      </link>

      <joint name='left_wheel_joint' type='revolute'>
        <parent>chassis</parent>
        <child>left_wheel</child>
        <axis>
          <xyz>0 0 1</xyz>
          <limit>
            <lower>-1e16</lower>
            <upper>1e16</upper>
          </limit>
        </axis>
      </joint>

      <joint name='right_wheel_joint' type='revolute'>
        <parent>chassis</parent>
        <child>right_wheel</child>
        <axis>
          <xyz>0 0 1</xyz>
          <limit>
            <lower>-1e16</lower>
            <upper>1e16</upper>
          </limit>
        </axis>
      </joint>

      <joint name='caster_joint' type='ball'>
        <parent>chassis</parent>
        <child>caster</child>
      </joint>

      <plugin name='diff_drive' filename='libDiffDrive.so'>
        <left_joint>left_wheel_joint</left_joint>
        <right_joint>right_wheel_joint</right_joint>
        <wheel_separation>0.6</wheel_separation>
        <wheel_radius>0.15</wheel_radius>
      </plugin>
    </model>

    <!-- A directional sun light -->
    <light name='sun' type='directional'>
      <cast_shadows>true</cast_shadows>
      <diffuse>0.8 0.8 0.8 1</diffuse>
      <specular>0.2 0.2 0.2 1</specular>
      <direction>-0.5 0.1 -0.9</direction>
    </light>

  </world>
</sdf>
